Workbook

Sheet Sheet1
D2: Year
D3: 0 | E3: =+D3+1 -> 1 | F3: =+E3+1 -> 2 | G3: =+F3+1 -> 3 | H3: =+G3+1 -> 4 | I3: =+H3+1 -> 5 | J3: =+I3+1 -> 6
C4: Gross Revenue | D4: 967000 | E4: =+D4*(1+E5) -> 967000 | F4: =+E4*(1+F5) -> 996010 | G4: =+F4*(1+G5) -> 1025890.3 | H4: =+G4*(1+H5) -> 1056667 | I4: =+H4*(1+I5) -> 1088367 | J4: =+I4*(1+J5) -> 1121018
C5: Revenue Growth | E5: 0 | F5: 0.03 | G5: 0.03 | H5: 0.03 | I5: 0.03 | J5: 0.03
C6: Average | E6: 0.0275 | F6: 0.0275 | G6: 0.0275 | H6: 0.0275 | I6: 0.0275 | J6: 0.0275
C8: Commission | E8: =+E4*E9 -> 477910.74 | F8: =+F4*F9 -> 492248.06 | G8: =+G4*G9 -> 507015.5 | H8: =+H4*H9 -> 522225.97 | I8: =+I4*I9 -> 537892.75 | J8: =+J4*J9 -> 554029.53
E9: =+SUMPRODUCT(D13:D20,D23:D30) -> 0.49422 | F9: =+$E$9 -> 0.49422 | G9: =+$E$9 -> 0.49422 | H9: =+$E$9 -> 0.49422 | I9: =+$E$9 -> 0.49422 | J9: =+$E$9 -> 0.49422
C12: Contract Commission Rates
C13: Labor Income | D13: 0.49
C14: Equipment Income | D14: 0.49
C15: Logistics Income | D15: 0.49
C16: Consumable / Sale Item Income | D16: 0.49
C17: Creative Content Income | D17: 0.3
C18: Rigging Income | D18: 0.3
C19: Power Income | D19: 0.75
C20: HSIA Icome | D20: 0.75
C22: Sales By Category
C23: Labor Income | D23: 0.4003
C24: Equipment Income | D24: 0.5611
C25: Logistics Income | D25: 0.0196
C26: Consumable / Sale Item Income | D26: 0
C27: Creative Content Income | D27: 0.0014
C28: Rigging Income | D28: 0.0002
C29: Power Income | D29: 0
C30: HSIA Icome | D30: 0.0174
C34: Net Revenue | E34: =+E4-E8 -> 489089.26 | F34: =+F4-F8 -> 503761.94 | G34: =+G4-G8 -> 518874.8 | H34: =+H4-H8 -> 534441.04 | I34: =+I4-I8 -> 550474.27 | J34: =+J4-J8 -> 566988.5
C36: COGS | E36: =+E34*E37 -> 48908.926 | F36: =+F34*F37 -> 50376.194 | G36: =+G34*G37 -> 51887.48 | H36: =+H34*H37 -> 53444.104 | I36: =+I34*I37 -> 55047.427 | J36: =+J34*J37 -> 56698.85
E37: 0.1 | F37: 0.1 | G37: 0.1 | H37: 0.1 | I37: 0.1 | J37: 0.1
C40: Payroll | E40: =+SUMIFS('Payroll Calculation'!H:H,'Payroll Calculation'!$B:$B,"Salary")+(($F$61*E4)+$F$62*(E4-E8)) -> 247731.23 | F40: =+SUMIFS('Payroll Calculation'!I:I,'Payroll Calculation'!$B:$B,"Salary")+(($F$61*F4)+$F$62*(F4-F8)) -> 255163.17 | G40: =+SUMIFS('Payroll Calculation'!J:J,'Payroll Calculation'!$B:$B,"Salary")+(($F$61*G4)+$F$62*(G4-G8)) -> 262818.06 | H40: =+SUMIFS('Payroll Calculation'!K:K,'Payroll Calculation'!$B:$B,"Salary")+(($F$61*H4)+$F$62*(H4-H8)) -> 270702.6 | I40: =+SUMIFS('Payroll Calculation'!L:L,'Payroll Calculation'!$B:$B,"Salary")+(($F$61*I4)+$F$62*(I4-I8)) -> 278823.68 | J40: =+SUMIFS('Payroll Calculation'!M:M,'Payroll Calculation'!$B:$B,"Salary")+(($F$61*J4)+$F$62*(J4-J8)) -> 287188.39
E41: =+E40/(E4-E8) -> 0.50651537 | F41: =+F40/(F4-F8) -> 0.50651537 | G41: =+G40/(G4-G8) -> 0.50651537 | H41: =+H40/(H4-H8) -> 0.50651537 | I41: =+I40/(I4-I8) -> 0.50651537 | J41: =+J40/(J4-J8) -> 0.50651537
C43: Merit Increase % | D43: 0.03
C45: Type | D45: Title | E45: Start Date | F45: Salary | G45: Salary w/Benefits
B46: 1 | C46: Salaried Full Time Staff | D46: Director | E46: -2 | F46: 78000 | G46: =+F46*(1+0.133) -> 88374
B47: =+B46+1 -> 2 | C47: Salaried Full Time Staff | D47: Technical Coordinator 1 | E47: -2 | F47: 55000 | G47: =+F47*(1+0.133) -> 62315
B48: =+B47+1 -> 3 | C48: Salaried Full Time Staff | D48: Technical Coordinator 2 | E48: -2 | F48: 0 | G48: =+F48*(1+0.133) -> 0
B49: =+B48+1 -> 4 | C49: Salaried Full Time Staff | D49: Technical Coordinator 3 | E49: -2 | F49: 0 | G49: =+F49*(1+0.133) -> 0
B50: =+B49+1 -> 5 | C50: Salaried Full Time Staff | D50: Technical Coordinator 4 | E50: -2 | F50: 0 | G50: =+F50*(1+0.133) -> 0
B51: =+B50+1 -> 6 | C51: Hourly Full Time Staff | D51: Technician 1 | E51: -2 | F51: 45670 | G51: =+F51*(1+0.133) -> 51744.11
B52: =+B51+1 -> 7 | C52: Hourly Full Time Staff | D52: Technician 2 | E52: -2 | F52: 0 | G52: =+F52*(1+0.133) -> 0
B53: =+B52+1 -> 8 | C53: Hourly Full Time Staff | D53: Technician 3 | E53: -2 | F53: 0 | G53: =+F53*(1+0.133) -> 0
...

Sheet Payroll Calculation
C3: Start Month | D3: Merit Increase | E3: Base Salary | G3: Year 0 | H3: Year 1 | I3: Year 2 | J3: Year 3 | K3: Year 4 | L3: Year 5 | M3: Year 6 | N3: Year 7 | O3: Year 8 | P3: Year 9 | Q3: Year 10
B4: Salary | C4: -1 | D4: =+Sheet1!$D$43 -> 0.03 | E4: =+Sheet1!$G$46 -> 88374 | G4: =E4*((1+D4)^G10*G11+(1+D4)^(G10+1)*G12)/12 -> 7364.5 | H4: =E4*((1+D4)^H10*H11+(1+D4)^(H10+1)*H12)/12 -> 88594.935 | I4: =E4*((1+D4)^I10*I11+(1+D4)^(I10+1)*I12)/12 -> 91252.783 | J4: =E4*((1+D4)^J10*J11+(1+D4)^(J10+1)*J12)/12 -> 93990.367 | K4: =E4*((1+D4)^K10*K11+(1+D4)^(K10+1)*K12)/12 -> 96810.078 | L4: =E4*((1+D4)^L10*L11+(1+D4)^(L10+1)*L12)/12 -> 99714.38 | M4: =E4*((1+D4)^M10*M11+(1+D4)^(M10+1)*M12)/12 -> 102705.81 | N4: =E4*((1+D4)^N10*N11+(1+D4)^(N10+1)*N12)/12 -> 105786.99 | O4: =E4*((1+D4)^O10*O11+(1+D4)^(O10+1)*O12)/12 -> 108960.6 | P4: =E4*((1+D4)^P10*P11+(1+D4)^(P10+1)*P12)/12 -> 112229.41 | Q4: =E4*((1+D4)^Q10*Q11+(1+D4)^(Q10+1)*Q12)/12 -> 115596.3
B5: Effective Annual Rate | G5: =IF(G6=0,0,G4/G6*12) -> 88374 | H5: =IF(H6=0,0,H4/H6*12) -> 88594.935 | I5: =IF(I6=0,0,I4/I6*12) -> 91252.783 | J5: =IF(J6=0,0,J4/J6*12) -> 93990.367 | K5: =IF(K6=0,0,K4/K6*12) -> 96810.078 | L5: =IF(L6=0,0,L4/L6*12) -> 99714.38 | M5: =IF(M6=0,0,M4/M6*12) -> 102705.81 | N5: =IF(N6=0,0,N4/N6*12) -> 105786.99 | ... Q5: =IF(Q6=0,0,Q4/Q6*12) -> 115596.3
B6: Months Worked | G6: =+G9-G8 -> 1 | H6: =+H9-H8 -> 12 | I6: =+I9-I8 -> 12 | J6: =+J9-J8 -> 12 | K6: =+K9-K8 -> 12 | L6: =+L9-L8 -> 12 | M6: =+M9-M8 -> 12 | N6: =+N9-N8 -> 12 | ... Q6: =+Q9-Q8 -> 12
B7: Year Index (n) | G7: 0 | H7: 1 | I7: 2 | J7: 3 | K7: 4 | L7: 5 | M7: 6 | N7: 7 | O7: 8 | P7: 9 | Q7: 10
B8: Service Months @ Yr Start | G8: =MAX(0,12*(G7-1)-C4) -> 0 | H8: =MAX(0,12*(H7-1)-C4) -> 1 | I8: =MAX(0,12*(I7-1)-C4) -> 13 | J8: =MAX(0,12*(J7-1)-C4) -> 25 | K8: =MAX(0,12*(K7-1)-C4) -> 37 | L8: =MAX(0,12*(L7-1)-C4) -> 49 | M8: =MAX(0,12*(M7-1)-C4) -> 61 | N8: =MAX(0,12*(N7-1)-C4) -> 73 | O8: =MAX(0,12*(O7-1)-C4) -> 85 | P8: =MAX(0,12*(P7-1)-C4) -> 97 | Q8: =MAX(0,12*(Q7-1)-C4) -> 109
B9: Service Months @ Yr End | G9: =MAX(0,12*G7-C4) -> 1 | H9: =MAX(0,12*H7-C4) -> 13 | I9: =MAX(0,12*I7-C4) -> 25 | J9: =MAX(0,12*J7-C4) -> 37 | K9: =MAX(0,12*K7-C4) -> 49 | L9: =MAX(0,12*L7-C4) -> 61 | M9: =MAX(0,12*M7-C4) -> 73 | N9: =MAX(0,12*N7-C4) -> 85 | O9: =MAX(0,12*O7-C4) -> 97 | P9: =MAX(0,12*P7-C4) -> 109 | Q9: =MAX(0,12*Q7-C4) -> 121
B10: Completed Service Yrs (k) | G10: =INT(G8/12) -> 0 | H10: =INT(H8/12) -> 0 | I10: =INT(I8/12) -> 1 | J10: =INT(J8/12) -> 2 | K10: =INT(K8/12) -> 3 | L10: =INT(L8/12) -> 4 | M10: =INT(M8/12) -> 5 | N10: =INT(N8/12) -> 6 | ... Q10: =INT(Q8/12) -> 9
B11: Months at Rate k | G11: =MIN(G9,12*(G10+1))-G8 -> 1 | H11: =MIN(H9,12*(H10+1))-H8 -> 11 | I11: =MIN(I9,12*(I10+1))-I8 -> 11 | J11: =MIN(J9,12*(J10+1))-J8 -> 11 | K11: =MIN(K9,12*(K10+1))-K8 -> 11 | L11: =MIN(L9,12*(L10+1))-L8 -> 11 | M11: =MIN(M9,12*(M10+1))-M8 -> 11 | N11: =MIN(N9,12*(N10+1))-N8 -> 11 | ... Q11: =MIN(Q9,12*(Q10+1))-Q8 -> 11
B12: Months at Rate k+1 | G12: =+G9-MIN(G9,12*(G10+1)) -> 0 | H12: =+H9-MIN(H9,12*(H10+1)) -> 1 | I12: =+I9-MIN(I9,12*(I10+1)) -> 1 | J12: =+J9-MIN(J9,12*(J10+1)) -> 1 | K12: =+K9-MIN(K9,12*(K10+1)) -> 1 | L12: =+L9-MIN(L9,12*(L10+1)) -> 1 | M12: =+M9-MIN(M9,12*(M10+1)) -> 1 | N12: =+N9-MIN(N9,12*(N10+1)) -> 1 | ... Q12: =+Q9-MIN(Q9,12*(Q10+1)) -> 1
C14: Start Month | D14: Merit Increase | E14: Base Salary | G14: Year 0 | H14: Year 1 | I14: Year 2 | J14: Year 3 | K14: Year 4 | L14: Year 5 | M14: Year 6 | N14: Year 7 | O14: Year 8 | P14: Year 9 | Q14: Year 10
B15: Salary | C15: -1 | D15: =+Sheet1!$D$43 -> 0.03 | E15: =+Sheet1!$G$47 -> 62315 | G15: =E15*((1+D15)^G21*G22+(1+D15)^(G21+1)*G23)/12 -> 5192.9167 | H15: =E15*((1+D15)^H21*H22+(1+D15)^(H21+1)*H23)/12 -> 62470.787 | I15: =E15*((1+D15)^I21*I22+(1+D15)^(I21+1)*I23)/12 -> 64344.911 | J15: =E15*((1+D15)^J21*J22+(1+D15)^(J21+1)*J23)/12 -> 66275.258 | K15: =E15*((1+D15)^K21*K22+(1+D15)^(K21+1)*K23)/12 -> 68263.516 | L15: =E15*((1+D15)^L21*L22+(1+D15)^(L21+1)*L23)/12 -> 70311.422 | M15: =E15*((1+D15)^M21*M22+(1+D15)^(M21+1)*M23)/12 -> 72420.764 | N15: =E15*((1+D15)^N21*N22+(1+D15)^(N21+1)*N23)/12 -> 74593.387 | O15: =E15*((1+D15)^O21*O22+(1+D15)^(O21+1)*O23)/12 -> 76831.189 | P15: =E15*((1+D15)^P21*P22+(1+D15)^(P21+1)*P23)/12 -> 79136.125 | Q15: =E15*((1+D15)^Q21*Q22+(1+D15)^(Q21+1)*Q23)/12 -> 81510.208
B16: Effective Annual Rate | G16: =IF(G17=0,0,G15/G17*12) -> 62315 | H16: =IF(H17=0,0,H15/H17*12) -> 62470.787 | I16: =IF(I17=0,0,I15/I17*12) -> 64344.911 | J16: =IF(J17=0,0,J15/J17*12) -> 66275.258 | K16: =IF(K17=0,0,K15/K17*12) -> 68263.516 | L16: =IF(L17=0,0,L15/L17*12) -> 70311.422 | M16: =IF(M17=0,0,M15/M17*12) -> 72420.764 | N16: =IF(N17=0,0,N15/N17*12) -> 74593.387 | ... Q16: =IF(Q17=0,0,Q15/Q17*12) -> 81510.208
B17: Months Worked | G17: =+G20-G19 -> 1 | H17: =+H20-H19 -> 12 | I17: =+I20-I19 -> 12 | J17: =+J20-J19 -> 12 | K17: =+K20-K19 -> 12 | L17: =+L20-L19 -> 12 | M17: =+M20-M19 -> 12 | N17: =+N20-N19 -> 12 | ... Q17: =+Q20-Q19 -> 12
B18: Year Index (n) | G18: 0 | H18: 1 | I18: 2 | J18: 3 | K18: 4 | L18: 5 | M18: 6 | N18: 7 | O18: 8 | P18: 9 | Q18: 10
B19: Service Months @ Yr Start | G19: =MAX(0,12*(G18-1)-C15) -> 0 | H19: =MAX(0,12*(H18-1)-C15) -> 1 | I19: =MAX(0,12*(I18-1)-C15) -> 13 | J19: =MAX(0,12*(J18-1)-C15) -> 25 | K19: =MAX(0,12*(K18-1)-C15) -> 37 | L19: =MAX(0,12*(L18-1)-C15) -> 49 | M19: =MAX(0,12*(M18-1)-C15) -> 61 | N19: =MAX(0,12*(N18-1)-C15) -> 73 | O19: =MAX(0,12*(O18-1)-C15) -> 85 | P19: =MAX(0,12*(P18-1)-C15) -> 97 | Q19: =MAX(0,12*(Q18-1)-C15) -> 109
B20: Service Months @ Yr End | G20: =MAX(0,12*G18-C15) -> 1 | H20: =MAX(0,12*H18-C15) -> 13 | I20: =MAX(0,12*I18-C15) -> 25 | J20: =MAX(0,12*J18-C15) -> 37 | K20: =MAX(0,12*K18-C15) -> 49 | L20: =MAX(0,12*L18-C15) -> 61 | M20: =MAX(0,12*M18-C15) -> 73 | N20: =MAX(0,12*N18-C15) -> 85 | O20: =MAX(0,12*O18-C15) -> 97 | P20: =MAX(0,12*P18-C15) -> 109 | Q20: =MAX(0,12*Q18-C15) -> 121
B21: Completed Service Yrs (k) | G21: =INT(G19/12) -> 0 | H21: =INT(H19/12) -> 0 | I21: =INT(I19/12) -> 1 | J21: =INT(J19/12) -> 2 | K21: =INT(K19/12) -> 3 | L21: =INT(L19/12) -> 4 | M21: =INT(M19/12) -> 5 | N21: =INT(N19/12) -> 6 | ... Q21: =INT(Q19/12) -> 9
B22: Months at Rate k | G22: =MIN(G20,12*(G21+1))-G19 -> 1 | H22: =MIN(H20,12*(H21+1))-H19 -> 11 | I22: =MIN(I20,12*(I21+1))-I19 -> 11 | J22: =MIN(J20,12*(J21+1))-J19 -> 11 | K22: =MIN(K20,12*(K21+1))-K19 -> 11 | L22: =MIN(L20,12*(L21+1))-L19 -> 11 | M22: =MIN(M20,12*(M21+1))-M19 -> 11 | N22: =MIN(N20,12*(N21+1))-N19 -> 11 | ... Q22: =MIN(Q20,12*(Q21+1))-Q19 -> 11
B23: Months at Rate k+1 | G23: =+G20-MIN(G20,12*(G21+1)) -> 0 | H23: =+H20-MIN(H20,12*(H21+1)) -> 1 | I23: =+I20-MIN(I20,12*(I21+1)) -> 1 | J23: =+J20-MIN(J20,12*(J21+1)) -> 1 | K23: =+K20-MIN(K20,12*(K21+1)) -> 1 | L23: =+L20-MIN(L20,12*(L21+1)) -> 1 | M23: =+M20-MIN(M20,12*(M21+1)) -> 1 | N23: =+N20-MIN(N20,12*(N21+1)) -> 1 | ... Q23: =+Q20-MIN(Q20,12*(Q21+1)) -> 1
C25: Start Month | D25: Merit Increase | E25: Base Salary | G25: Year 0 | H25: Year 1 | I25: Year 2 | J25: Year 3 | K25: Year 4 | L25: Year 5 | M25: Year 6 | N25: Year 7 | O25: Year 8 | P25: Year 9 | Q25: Year 10
B26: Salary | C26: -1 | D26: =+Sheet1!$D$43 -> 0.03 | E26: =+Sheet1!$G$48 -> 0 | G26: =E26*((1+D26)^G32*G33+(1+D26)^(G32+1)*G34)/12 -> 0 | H26: =E26*((1+D26)^H32*H33+(1+D26)^(H32+1)*H34)/12 -> 0 | I26: =E26*((1+D26)^I32*I33+(1+D26)^(I32+1)*I34)/12 -> 0 | J26: =E26*((1+D26)^J32*J33+(1+D26)^(J32+1)*J34)/12 -> 0 | K26: =E26*((1+D26)^K32*K33+(1+D26)^(K32+1)*K34)/12 -> 0 | L26: =E26*((1+D26)^L32*L33+(1+D26)^(L32+1)*L34)/12 -> 0 | M26: =E26*((1+D26)^M32*M33+(1+D26)^(M32+1)*M34)/12 -> 0 | N26: =E26*((1+D26)^N32*N33+(1+D26)^(N32+1)*N34)/12 -> 0 | O26: =E26*((1+D26)^O32*O33+(1+D26)^(O32+1)*O34)/12 -> 0 | P26: =E26*((1+D26)^P32*P33+(1+D26)^(P32+1)*P34)/12 -> 0 | Q26: =E26*((1+D26)^Q32*Q33+(1+D26)^(Q32+1)*Q34)/12 -> 0
B27: Effective Annual Rate | G27: =IF(G28=0,0,G26/G28*12) -> 0 | H27: =IF(H28=0,0,H26/H28*12) -> 0 | I27: =IF(I28=0,0,I26/I28*12) -> 0 | J27: =IF(J28=0,0,J26/J28*12) -> 0 | K27: =IF(K28=0,0,K26/K28*12) -> 0 | L27: =IF(L28=0,0,L26/L28*12) -> 0 | M27: =IF(M28=0,0,M26/M28*12) -> 0 | N27: =IF(N28=0,0,N26/N28*12) -> 0 | ... Q27: =IF(Q28=0,0,Q26/Q28*12) -> 0
B28: Months Worked | G28: =+G31-G30 -> 1 | H28: =+H31-H30 -> 12 | I28: =+I31-I30 -> 12 | J28: =+J31-J30 -> 12 | K28: =+K31-K30 -> 12 | L28: =+L31-L30 -> 12 | M28: =+M31-M30 -> 12 | N28: =+N31-N30 -> 12 | ... Q28: =+Q31-Q30 -> 12
B29: Year Index (n) | G29: 0 | H29: 1 | I29: 2 | J29: 3 | K29: 4 | L29: 5 | M29: 6 | N29: 7 | O29: 8 | P29: 9 | Q29: 10
B30: Service Months @ Yr Start | G30: =MAX(0,12*(G29-1)-C26) -> 0 | H30: =MAX(0,12*(H29-1)-C26) -> 1 | I30: =MAX(0,12*(I29-1)-C26) -> 13 | J30: =MAX(0,12*(J29-1)-C26) -> 25 | K30: =MAX(0,12*(K29-1)-C26) -> 37 | L30: =MAX(0,12*(L29-1)-C26) -> 49 | M30: =MAX(0,12*(M29-1)-C26) -> 61 | N30: =MAX(0,12*(N29-1)-C26) -> 73 | O30: =MAX(0,12*(O29-1)-C26) -> 85 | P30: =MAX(0,12*(P29-1)-C26) -> 97 | Q30: =MAX(0,12*(Q29-1)-C26) -> 109
B31: Service Months @ Yr End | G31: =MAX(0,12*G29-C26) -> 1 | H31: =MAX(0,12*H29-C26) -> 13 | I31: =MAX(0,12*I29-C26) -> 25 | J31: =MAX(0,12*J29-C26) -> 37 | K31: =MAX(0,12*K29-C26) -> 49 | L31: =MAX(0,12*L29-C26) -> 61 | M31: =MAX(0,12*M29-C26) -> 73 | N31: =MAX(0,12*N29-C26) -> 85 | O31: =MAX(0,12*O29-C26) -> 97 | P31: =MAX(0,12*P29-C26) -> 109 | Q31: =MAX(0,12*Q29-C26) -> 121
B32: Completed Service Yrs (k) | G32: =INT(G30/12) -> 0 | H32: =INT(H30/12) -> 0 | I32: =INT(I30/12) -> 1 | J32: =INT(J30/12) -> 2 | K32: =INT(K30/12) -> 3 | L32: =INT(L30/12) -> 4 | M32: =INT(M30/12) -> 5 | N32: =INT(N30/12) -> 6 | ... Q32: =INT(Q30/12) -> 9
B33: Months at Rate k | G33: =MIN(G31,12*(G32+1))-G30 -> 1 | H33: =MIN(H31,12*(H32+1))-H30 -> 11 | I33: =MIN(I31,12*(I32+1))-I30 -> 11 | J33: =MIN(J31,12*(J32+1))-J30 -> 11 | K33: =MIN(K31,12*(K32+1))-K30 -> 11 | L33: =MIN(L31,12*(L32+1))-L30 -> 11 | M33: =MIN(M31,12*(M32+1))-M30 -> 11 | N33: =MIN(N31,12*(N32+1))-N30 -> 11 | ... Q33: =MIN(Q31,12*(Q32+1))-Q30 -> 11
B34: Months at Rate k+1 | G34: =+G31-MIN(G31,12*(G32+1)) -> 0 | H34: =+H31-MIN(H31,12*(H32+1)) -> 1 | I34: =+I31-MIN(I31,12*(I32+1)) -> 1 | J34: =+J31-MIN(J31,12*(J32+1)) -> 1 | K34: =+K31-MIN(K31,12*(K32+1)) -> 1 | L34: =+L31-MIN(L31,12*(L32+1)) -> 1 | M34: =+M31-MIN(M31,12*(M32+1)) -> 1 | N34: =+N31-MIN(N31,12*(N32+1)) -> 1 | ... Q34: =+Q31-MIN(Q31,12*(Q32+1)) -> 1
C36: Start Month | D36: Merit Increase | E36: Base Salary | G36: Year 0 | H36: Year 1 | I36: Year 2 | J36: Year 3 | K36: Year 4 | L36: Year 5 | M36: Year 6 | N36: Year 7 | O36: Year 8 | P36: Year 9 | Q36: Year 10
B37: Salary | C37: -1 | D37: =+Sheet1!$D$43 -> 0.03 | E37: =+Sheet1!$G$49 -> 0 | G37: =E37*((1+D37)^G43*G44+(1+D37)^(G43+1)*G45)/12 -> 0 | H37: =E37*((1+D37)^H43*H44+(1+D37)^(H43+1)*H45)/12 -> 0 | I37: =E37*((1+D37)^I43*I44+(1+D37)^(I43+1)*I45)/12 -> 0 | J37: =E37*((1+D37)^J43*J44+(1+D37)^(J43+1)*J45)/12 -> 0 | K37: =E37*((1+D37)^K43*K44+(1+D37)^(K43+1)*K45)/12 -> 0 | L37: =E37*((1+D37)^L43*L44+(1+D37)^(L43+1)*L45)/12 -> 0 | M37: =E37*((1+D37)^M43*M44+(1+D37)^(M43+1)*M45)/12 -> 0 | N37: =E37*((1+D37)^N43*N44+(1+D37)^(N43+1)*N45)/12 -> 0 | O37: =E37*((1+D37)^O43*O44+(1+D37)^(O43+1)*O45)/12 -> 0 | P37: =E37*((1+D37)^P43*P44+(1+D37)^(P43+1)*P45)/12 -> 0 | Q37: =E37*((1+D37)^Q43*Q44+(1+D37)^(Q43+1)*Q45)/12 -> 0
B38: Effective Annual Rate | G38: =IF(G39=0,0,G37/G39*12) -> 0 | H38: =IF(H39=0,0,H37/H39*12) -> 0 | I38: =IF(I39=0,0,I37/I39*12) -> 0 | J38: =IF(J39=0,0,J37/J39*12) -> 0 | K38: =IF(K39=0,0,K37/K39*12) -> 0 | L38: =IF(L39=0,0,L37/L39*12) -> 0 | M38: =IF(M39=0,0,M37/M39*12) -> 0 | N38: =IF(N39=0,0,N37/N39*12) -> 0 | ... Q38: =IF(Q39=0,0,Q37/Q39*12) -> 0
B39: Months Worked | G39: =+G42-G41 -> 1 | H39: =+H42-H41 -> 12 | I39: =+I42-I41 -> 12 | J39: =+J42-J41 -> 12 | K39: =+K42-K41 -> 12 | L39: =+L42-L41 -> 12 | M39: =+M42-M41 -> 12 | N39: =+N42-N41 -> 12 | ... Q39: =+Q42-Q41 -> 12
B40: Year Index (n) | G40: 0 | H40: 1 | I40: 2 | J40: 3 | K40: 4 | L40: 5 | M40: 6 | N40: 7 | O40: 8 | P40: 9 | Q40: 10
B41: Service Months @ Yr Start | G41: =MAX(0,12*(G40-1)-C37) -> 0 | H41: =MAX(0,12*(H40-1)-C37) -> 1 | I41: =MAX(0,12*(I40-1)-C37) -> 13 | J41: =MAX(0,12*(J40-1)-C37) -> 25 | K41: =MAX(0,12*(K40-1)-C37) -> 37 | L41: =MAX(0,12*(L40-1)-C37) -> 49 | M41: =MAX(0,12*(M40-1)-C37) -> 61 | N41: =MAX(0,12*(N40-1)-C37) -> 73 | O41: =MAX(0,12*(O40-1)-C37) -> 85 | P41: =MAX(0,12*(P40-1)-C37) -> 97 | Q41: =MAX(0,12*(Q40-1)-C37) -> 109
B42: Service Months @ Yr End | G42: =MAX(0,12*G40-C37) -> 1 | H42: =MAX(0,12*H40-C37) -> 13 | I42: =MAX(0,12*I40-C37) -> 25 | J42: =MAX(0,12*J40-C37) -> 37 | K42: =MAX(0,12*K40-C37) -> 49 | L42: =MAX(0,12*L40-C37) -> 61 | M42: =MAX(0,12*M40-C37) -> 73 | N42: =MAX(0,12*N40-C37) -> 85 | O42: =MAX(0,12*O40-C37) -> 97 | P42: =MAX(0,12*P40-C37) -> 109 | Q42: =MAX(0,12*Q40-C37) -> 121
B43: Completed Service Yrs (k) | G43: =INT(G41/12) -> 0 | H43: =INT(H41/12) -> 0 | I43: =INT(I41/12) -> 1 | J43: =INT(J41/12) -> 2 | K43: =INT(K41/12) -> 3 | L43: =INT(L41/12) -> 4 | M43: =INT(M41/12) -> 5 | N43: =INT(N41/12) -> 6 | ... Q43: =INT(Q41/12) -> 9
B44: Months at Rate k | G44: =MIN(G42,12*(G43+1))-G41 -> 1 | H44: =MIN(H42,12*(H43+1))-H41 -> 11 | I44: =MIN(I42,12*(I43+1))-I41 -> 11 | J44: =MIN(J42,12*(J43+1))-J41 -> 11 | K44: =MIN(K42,12*(K43+1))-K41 -> 11 | L44: =MIN(L42,12*(L43+1))-L41 -> 11 | M44: =MIN(M42,12*(M43+1))-M41 -> 11 | N44: =MIN(N42,12*(N43+1))-N41 -> 11 | ... Q44: =MIN(Q42,12*(Q43+1))-Q41 -> 11
B45: Months at Rate k+1 | G45: =+G42-MIN(G42,12*(G43+1)) -> 0 | H45: =+H42-MIN(H42,12*(H43+1)) -> 1 | I45: =+I42-MIN(I42,12*(I43+1)) -> 1 | J45: =+J42-MIN(J42,12*(J43+1)) -> 1 | K45: =+K42-MIN(K42,12*(K43+1)) -> 1 | L45: =+L42-MIN(L42,12*(L43+1)) -> 1 | M45: =+M42-MIN(M42,12*(M43+1)) -> 1 | N45: =+N42-MIN(N42,12*(N43+1)) -> 1 | ... Q45: =+Q42-MIN(Q42,12*(Q43+1)) -> 1
...
